[2022-01-09 00:20:03] [ERROR] red.laggron.say: Exception in command 'interact'.

Traceback (most recent call last):
  File "C:\Users\HRIDAAN\redenv\lib\site-packages\aiohttp\connector.py", line 999, in _create_direct_connection
    hosts = await asyncio.shield(host_resolved)
  File "C:\Users\HRIDAAN\redenv\lib\site-packages\aiohttp\connector.py", line 865, in _resolve_host
    addrs = await self._resolver.resolve(host, port, family=self._family)
  File "C:\Users\HRIDAAN\redenv\lib\site-packages\aiohttp\resolver.py", line 31, in resolve
    infos = await self._loop.getaddrinfo(
  File "C:\Users\HRIDAAN\AppData\Local\Programs\Python\Python39\lib\asyncio\base_events.py", line 856, in getaddrinfo
    return await self.run_in_executor(
  File "C:\Users\HRIDAAN\AppData\Local\Programs\Python\Python39\lib\concurrent\futures\thread.py", line 52, in run
    result = self.fn(*self.args, **self.kwargs)
  File "C:\Users\HRIDAAN\AppData\Local\Programs\Python\Python39\lib\socket.py", line 954, in getaddrinfo
    for res in _socket.getaddrinfo(host, port, family, type, proto, flags):
socket.gaierror: [Errno 11001] getaddrinfo failed

The above exception was the direct cause of the following exception:

Traceback (most recent call last):
  File "C:\Users\HRIDAAN\redenv\lib\site-packages\discord\ext\commands\core.py", line 85, in wrapped
    ret = await coro(*args, **kwargs)
  File "C:\Users\HRIDAAN\AppData\Roaming\ducky\cogs\CogManager\cogs\say\say.py", line 252, in _interact
    await u.send(_("Request timed out. Session closed"))
  File "C:\Users\HRIDAAN\redenv\lib\site-packages\discord\http.py", line 192, in request
    async with self.__session.request(method, url, **kwargs) as r:
  File "C:\Users\HRIDAAN\redenv\lib\site-packages\aiohttp\client.py", line 1117, in __aenter__
    self._resp = await self._coro
  File "C:\Users\HRIDAAN\redenv\lib\site-packages\aiohttp\client.py", line 520, in _request
    conn = await self._connector.connect(
  File "C:\Users\HRIDAAN\redenv\lib\site-packages\aiohttp\connector.py", line 535, in connect
    proto = await self._create_connection(req, traces, timeout)
  File "C:\Users\HRIDAAN\redenv\lib\site-packages\aiohttp\connector.py", line 892, in _create_connection
    _, proto = await self._create_direct_connection(req, traces, timeout)
  File "C:\Users\HRIDAAN\redenv\lib\site-packages\aiohttp\connector.py", line 1011, in _create_direct_connection
    raise ClientConnectorError(req.connection_key, exc) from exc
aiohttp.client_exceptions.ClientConnectorError: Cannot connect to host discord.com:443 ssl:default [getaddrinfo failed]
[2022-01-11 22:51:47] [ERROR] red.laggron.say: Exception in command 'saym'.

Traceback (most recent call last):
  File "C:\Users\HRIDAAN\redenv\lib\site-packages\discord\ext\commands\core.py", line 85, in wrapped
    ret = await coro(*args, **kwargs)
  File "C:\Users\HRIDAAN\AppData\Roaming\ducky\cogs\CogManager\cogs\say\say.py", line 172, in _saymention
    role_mentions = message.role_mentions
AttributeError: role_mentions
